=== Execution at 2024-06-24 23:48:54.385606 ===
Traceback (most recent call last):
  File "C:\Users\joao_\AppData\Local\Programs\Python\Python312\Lib\site-packages\instagrapi\mixins\private.py", line 359, in _send_private_request
    response.raise_for_status()
  File "C:\Users\joao_\AppData\Local\Programs\Python\Python312\Lib\site-packages\requests\models.py", line 1024, in raise_for_status
    raise HTTPError(http_error_msg, response=self)
requests.exceptions.HTTPError: 400 Client Error: Bad Request for url: https://i.instagram.com/api/v1/accounts/login/

During handling of the above exception, another exception occurred:

Traceback (most recent call last):
  File "C:\Users\joao_\Desktop\Perdix\Faculdade\Mestrado\1_ano\2_semestre\Criatividade_computacional\instagram-bot\parabens-instagram-bot\instagram-bot.py", line 15, in <module>
    client.login(username, password)
  File "C:\Users\joao_\AppData\Local\Programs\Python\Python312\Lib\site-packages\instagrapi\mixins\auth.py", line 441, in login
    logged = self.private_request("accounts/login/", data, login=True)
             ^^^^^^^^^^^^^^^^^^^^^^^^^^^^^^^^^^^^^^^^^^^^^^^^^^^^^^^^^
  File "C:\Users\joao_\AppData\Local\Programs\Python\Python312\Lib\site-packages\instagrapi\mixins\private.py", line 541, in private_request
    raise e
  File "C:\Users\joao_\AppData\Local\Programs\Python\Python312\Lib\site-packages\instagrapi\mixins\private.py", line 526, in private_request
    self._send_private_request(endpoint, **kwargs)
  File "C:\Users\joao_\AppData\Local\Programs\Python\Python312\Lib\site-packages\instagrapi\mixins\private.py", line 382, in _send_private_request
    raise PleaseWaitFewMinutes(e, response=e.response, **last_json)
instagrapi.exceptions.PleaseWaitFewMinutes: Please wait a few minutes before you try again.


=== Execution at 2024-06-24 23:50:08.565196 ===
Traceback (most recent call last):
  File "C:\Users\joao_\AppData\Local\Programs\Python\Python312\Lib\site-packages\instagrapi\mixins\private.py", line 359, in _send_private_request
    response.raise_for_status()
  File "C:\Users\joao_\AppData\Local\Programs\Python\Python312\Lib\site-packages\requests\models.py", line 1024, in raise_for_status
    raise HTTPError(http_error_msg, response=self)
requests.exceptions.HTTPError: 400 Client Error: Bad Request for url: https://i.instagram.com/api/v1/accounts/login/

During handling of the above exception, another exception occurred:

Traceback (most recent call last):
  File "C:\Users\joao_\Desktop\Perdix\Faculdade\Mestrado\1_ano\2_semestre\Criatividade_computacional\instagram-bot\parabens-instagram-bot\instagram-bot.py", line 15, in <module>
    client.login(username, password)
  File "C:\Users\joao_\AppData\Local\Programs\Python\Python312\Lib\site-packages\instagrapi\mixins\auth.py", line 441, in login
    logged = self.private_request("accounts/login/", data, login=True)
             ^^^^^^^^^^^^^^^^^^^^^^^^^^^^^^^^^^^^^^^^^^^^^^^^^^^^^^^^^
  File "C:\Users\joao_\AppData\Local\Programs\Python\Python312\Lib\site-packages\instagrapi\mixins\private.py", line 541, in private_request
    raise e
  File "C:\Users\joao_\AppData\Local\Programs\Python\Python312\Lib\site-packages\instagrapi\mixins\private.py", line 526, in private_request
    self._send_private_request(endpoint, **kwargs)
  File "C:\Users\joao_\AppData\Local\Programs\Python\Python312\Lib\site-packages\instagrapi\mixins\private.py", line 382, in _send_private_request
    raise PleaseWaitFewMinutes(e, response=e.response, **last_json)
instagrapi.exceptions.PleaseWaitFewMinutes: Please wait a few minutes before you try again.


