=== Execution at 2024-07-11 19:32:22.277646 ===
Traceback (most recent call last):
  File "C:\Users\joao_\AppData\Local\Programs\Python\Python312\Lib\site-packages\instagrapi\mixins\private.py", line 359, in _send_private_request
    response.raise_for_status()
  File "C:\Users\joao_\AppData\Local\Programs\Python\Python312\Lib\site-packages\requests\models.py", line 1024, in raise_for_status
    raise HTTPError(http_error_msg, response=self)
requests.exceptions.HTTPError: 400 Client Error: Bad Request for url: https://i.instagram.com/api/v1/feed/reels_tray/

During handling of the above exception, another exception occurred:

Traceback (most recent call last):
  File "C:\Users\joao_\AppData\Local\Programs\Python\Python312\Lib\site-packages\instagrapi\mixins\private.py", line 526, in private_request
    self._send_private_request(endpoint, **kwargs)
  File "C:\Users\joao_\AppData\Local\Programs\Python\Python312\Lib\site-packages\instagrapi\mixins\private.py", line 392, in _send_private_request
    raise ChallengeRequired(**last_json)
instagrapi.exceptions.ChallengeRequired: challenge_required

During handling of the above exception, another exception occurred:

Traceback (most recent call last):
  File "C:\Users\joao_\Desktop\Perdix\Faculdade\Mestrado\1_ano\2_semestre\Criatividade_computacional\instagram-bot\parabens-instagram-bot\new_post.py", line 46, in <module>
    main()
  File "C:\Users\joao_\Desktop\Perdix\Faculdade\Mestrado\1_ano\2_semestre\Criatividade_computacional\instagram-bot\parabens-instagram-bot\new_post.py", line 36, in main
    client.login(username, password)
  File "C:\Users\joao_\AppData\Local\Programs\Python\Python312\Lib\site-packages\instagrapi\mixins\auth.py", line 472, in login
    self.login_flow()
  File "C:\Users\joao_\AppData\Local\Programs\Python\Python312\Lib\site-packages\instagrapi\mixins\auth.py", line 186, in login_flow
    check_flow.append(self.get_reels_tray_feed("cold_start"))
                      ^^^^^^^^^^^^^^^^^^^^^^^^^^^^^^^^^^^^^^
  File "C:\Users\joao_\AppData\Local\Programs\Python\Python312\Lib\site-packages\instagrapi\mixins\auth.py", line 277, in get_reels_tray_feed
    return self.private_request("feed/reels_tray/", data)
           ^^^^^^^^^^^^^^^^^^^^^^^^^^^^^^^^^^^^^^^^^^^^^^
  File "C:\Users\joao_\AppData\Local\Programs\Python\Python312\Lib\site-packages\instagrapi\mixins\private.py", line 539, in private_request
    self.challenge_resolve(self.last_json)
  File "C:\Users\joao_\AppData\Local\Programs\Python\Python312\Lib\site-packages\instagrapi\mixins\challenge.py", line 81, in challenge_resolve
    return self.challenge_resolve_simple(challenge_url)
           ^^^^^^^^^^^^^^^^^^^^^^^^^^^^^^^^^^^^^^^^^^^^
  File "C:\Users\joao_\AppData\Local\Programs\Python\Python312\Lib\site-packages\instagrapi\mixins\challenge.py", line 535, in challenge_resolve_simple
    raise ChallengeUnknownStep(
instagrapi.exceptions.ChallengeUnknownStep: ChallengeResolve: Unknown step_name "submit_phone" for "gratulationes0@gmail.com" in challenge resolver: {'step_name': 'submit_phone', 'step_data': {'phone_number': 'None', 'show_whatsapp_otp_choice': True, 'whatsapp': False}, 'flow_render_type': 3, 'bloks_action': 'com.instagram.challenge.navigation.take_challenge', 'cni': 17856100134211368, 'challenge_context': 'Af7Z5nJDn2pHlUPO76QL3TnVpW84QubVoBB0kGJxZcYplfjumn6GXLUzaGSso6tGqKZcKRHRw7xiNlgzVM9E7gDeM3MnNqBv7HqQv5e8dccEmGgxM3MxAD_WqRjRuGwC9nlkZ6dP0S9iB2QQJiGGSlLWI17P_UxHL4nO6bKNfffTnEDhLmD7OlgjSZfRWtvzG96vluYe0xsA23FVuuA9eG6wpPA06_AXCq9ByeW5OrSw', 'challenge_type_enum_str': 'SMS', 'status': 'ok'}


=== Execution at 2024-07-11 19:34:00.627390 ===
Traceback (most recent call last):
  File "C:\Users\joao_\AppData\Local\Programs\Python\Python312\Lib\site-packages\instagrapi\mixins\private.py", line 359, in _send_private_request
    response.raise_for_status()
  File "C:\Users\joao_\AppData\Local\Programs\Python\Python312\Lib\site-packages\requests\models.py", line 1024, in raise_for_status
    raise HTTPError(http_error_msg, response=self)
requests.exceptions.HTTPError: 400 Client Error: Bad Request for url: https://i.instagram.com/api/v1/feed/reels_tray/

During handling of the above exception, another exception occurred:

Traceback (most recent call last):
  File "C:\Users\joao_\AppData\Local\Programs\Python\Python312\Lib\site-packages\instagrapi\mixins\private.py", line 526, in private_request
    self._send_private_request(endpoint, **kwargs)
  File "C:\Users\joao_\AppData\Local\Programs\Python\Python312\Lib\site-packages\instagrapi\mixins\private.py", line 392, in _send_private_request
    raise ChallengeRequired(**last_json)
instagrapi.exceptions.ChallengeRequired: challenge_required

During handling of the above exception, another exception occurred:

Traceback (most recent call last):
  File "C:\Users\joao_\Desktop\Perdix\Faculdade\Mestrado\1_ano\2_semestre\Criatividade_computacional\instagram-bot\parabens-instagram-bot\new_post.py", line 46, in <module>
    main()
  File "C:\Users\joao_\Desktop\Perdix\Faculdade\Mestrado\1_ano\2_semestre\Criatividade_computacional\instagram-bot\parabens-instagram-bot\new_post.py", line 36, in main
    client.login(username, password)
  File "C:\Users\joao_\AppData\Local\Programs\Python\Python312\Lib\site-packages\instagrapi\mixins\auth.py", line 472, in login
    self.login_flow()
  File "C:\Users\joao_\AppData\Local\Programs\Python\Python312\Lib\site-packages\instagrapi\mixins\auth.py", line 186, in login_flow
    check_flow.append(self.get_reels_tray_feed("cold_start"))
                      ^^^^^^^^^^^^^^^^^^^^^^^^^^^^^^^^^^^^^^
  File "C:\Users\joao_\AppData\Local\Programs\Python\Python312\Lib\site-packages\instagrapi\mixins\auth.py", line 277, in get_reels_tray_feed
    return self.private_request("feed/reels_tray/", data)
           ^^^^^^^^^^^^^^^^^^^^^^^^^^^^^^^^^^^^^^^^^^^^^^
  File "C:\Users\joao_\AppData\Local\Programs\Python\Python312\Lib\site-packages\instagrapi\mixins\private.py", line 539, in private_request
    self.challenge_resolve(self.last_json)
  File "C:\Users\joao_\AppData\Local\Programs\Python\Python312\Lib\site-packages\instagrapi\mixins\challenge.py", line 81, in challenge_resolve
    return self.challenge_resolve_simple(challenge_url)
           ^^^^^^^^^^^^^^^^^^^^^^^^^^^^^^^^^^^^^^^^^^^^
  File "C:\Users\joao_\AppData\Local\Programs\Python\Python312\Lib\site-packages\instagrapi\mixins\challenge.py", line 535, in challenge_resolve_simple
    raise ChallengeUnknownStep(
instagrapi.exceptions.ChallengeUnknownStep: ChallengeResolve: Unknown step_name "submit_phone" for "gratulationes0@gmail.com" in challenge resolver: {'step_name': 'submit_phone', 'step_data': {'phone_number': 'None', 'show_whatsapp_otp_choice': True, 'whatsapp': False}, 'flow_render_type': 3, 'bloks_action': 'com.instagram.challenge.navigation.take_challenge', 'cni': 17856100134211368, 'challenge_context': 'Af6D3MZyhjIMnlshWjeu3HnO7iw0vfDPb4O9hxw8W91ewn02b3pY2nYJtCFWiOSeUKYfqMs1TIWByMd2xVphoI8MFpuEu4xL-csCkhaznApjzESVxjbisU9e9Z9CxNO5_UWLSJ0cesa9SgsWYh08WqlgGYOoYaH8H32AEhDO9q5svPXRJlmpBBSch8UbU4iI9z4CtRWG5PuQvgNNErqD-nnHbqnYUjTJXTEuGqGUyspC', 'challenge_type_enum_str': 'SMS', 'status': 'ok'}


=== Execution at 2024-07-11 20:05:22.884141 ===


